2022-04-23 14:40:42,333 INFO    MainThread:10707 [internal.py:wandb_internal():93] W&B internal server running at pid: 10707, started at: 2022-04-23 14:40:42.332887
2022-04-23 14:40:42,335 INFO    WriterThread:10707 [datastore.py:open_for_write():75] open: /data/codes/isedol_segmentation/wandb/run-20220423_144041-23plz8ui/run-23plz8ui.wandb
2022-04-23 14:40:42,338 DEBUG   SenderThread:10707 [sender.py:send():232] send: header
2022-04-23 14:40:42,338 DEBUG   SenderThread:10707 [sender.py:send():232] send: run
2022-04-23 14:40:42,573 ERROR   SenderThread:10707 [internal_api.py:execute():143] 404 response executing GraphQL.
2022-04-23 14:40:42,573 ERROR   SenderThread:10707 [internal_api.py:execute():144] {"errors":[{"message":"project not found","path":["upsertBucket"]}],"data":{"upsertBucket":null}}
2022-04-23 14:40:43,337 INFO    WriterThread:10707 [datastore.py:close():279] close: /data/codes/isedol_segmentation/wandb/run-20220423_144041-23plz8ui/run-23plz8ui.wandb
2022-04-23 14:40:43,337 INFO    HandlerThread:10707 [handler.py:finish():806] shutting down handler
2022-04-23 14:40:43,338 ERROR   MainThread:10707 [internal.py:wandb_internal():165] Thread SenderThread:
Traceback (most recent call last):
  File "/home/smartai/anaconda3/envs/seg/lib/python3.6/site-packages/wandb/sdk/lib/retry.py", line 102, in __call__
    result = self._call_fn(*args, **kwargs)
  File "/home/smartai/anaconda3/envs/seg/lib/python3.6/site-packages/wandb/sdk/internal/internal_api.py", line 140, in execute
    return self.client.execute(*args, **kwargs)
  File "/home/smartai/anaconda3/envs/seg/lib/python3.6/site-packages/wandb/vendor/gql-0.2.0/wandb_gql/client.py", line 52, in execute
    result = self._get_result(document, *args, **kwargs)
  File "/home/smartai/anaconda3/envs/seg/lib/python3.6/site-packages/wandb/vendor/gql-0.2.0/wandb_gql/client.py", line 60, in _get_result
    return self.transport.execute(document, *args, **kwargs)
  File "/home/smartai/anaconda3/envs/seg/lib/python3.6/site-packages/wandb/vendor/gql-0.2.0/wandb_gql/transport/requests.py", line 39, in execute
    request.raise_for_status()
  File "/home/smartai/anaconda3/envs/seg/lib/python3.6/site-packages/requests/models.py", line 960, in raise_for_status
    raise HTTPError(http_error_msg, response=self)
requests.exceptions.HTTPError: 404 Client Error: Not Found for url: https://api.wandb.ai/graphql

During handling of the above exception, another exception occurred:

Traceback (most recent call last):
  File "/home/smartai/anaconda3/envs/seg/lib/python3.6/site-packages/wandb/apis/normalize.py", line 22, in wrapper
    return func(*args, **kwargs)
  File "/home/smartai/anaconda3/envs/seg/lib/python3.6/site-packages/wandb/sdk/internal/internal_api.py", line 1318, in upsert_run
    response = self.gql(mutation, variable_values=variable_values, **kwargs)
  File "/home/smartai/anaconda3/envs/seg/lib/python3.6/site-packages/wandb/sdk/lib/retry.py", line 118, in __call__
    if not check_retry_fn(e):
  File "/home/smartai/anaconda3/envs/seg/lib/python3.6/site-packages/wandb/util.py", line 879, in no_retry_auth
    raise CommError("Permission denied, ask the project owner to grant you access")
wandb.errors.CommError: Permission denied, ask the project owner to grant you access

During handling of the above exception, another exception occurred:

Traceback (most recent call last):
  File "/home/smartai/anaconda3/envs/seg/lib/python3.6/site-packages/wandb/sdk/internal/internal_util.py", line 51, in run
    self._run()
  File "/home/smartai/anaconda3/envs/seg/lib/python3.6/site-packages/wandb/sdk/internal/internal_util.py", line 102, in _run
    self._process(record)
  File "/home/smartai/anaconda3/envs/seg/lib/python3.6/site-packages/wandb/sdk/internal/internal.py", line 310, in _process
    self._sm.send(record)
  File "/home/smartai/anaconda3/envs/seg/lib/python3.6/site-packages/wandb/sdk/internal/sender.py", line 234, in send
    send_handler(record)
  File "/home/smartai/anaconda3/envs/seg/lib/python3.6/site-packages/wandb/sdk/internal/sender.py", line 692, in send_run
    self._init_run(run, config_value_dict)
  File "/home/smartai/anaconda3/envs/seg/lib/python3.6/site-packages/wandb/sdk/internal/sender.py", line 730, in _init_run
    commit=run.git.last_commit or None,
  File "/home/smartai/anaconda3/envs/seg/lib/python3.6/site-packages/wandb/apis/normalize.py", line 58, in wrapper
    raise CommError(message, err).with_traceback(sys.exc_info()[2])
  File "/home/smartai/anaconda3/envs/seg/lib/python3.6/site-packages/wandb/apis/normalize.py", line 22, in wrapper
    return func(*args, **kwargs)
  File "/home/smartai/anaconda3/envs/seg/lib/python3.6/site-packages/wandb/sdk/internal/internal_api.py", line 1318, in upsert_run
    response = self.gql(mutation, variable_values=variable_values, **kwargs)
  File "/home/smartai/anaconda3/envs/seg/lib/python3.6/site-packages/wandb/sdk/lib/retry.py", line 118, in __call__
    if not check_retry_fn(e):
  File "/home/smartai/anaconda3/envs/seg/lib/python3.6/site-packages/wandb/util.py", line 879, in no_retry_auth
    raise CommError("Permission denied, ask the project owner to grant you access")
wandb.errors.CommError: Permission denied, ask the project owner to grant you access
2022-04-23 14:40:45,377 INFO    MainThread:10707 [internal.py:handle_exit():80] Internal process exited
